 Wed, 01 Apr 2020 21:41:15  INFO test_sellset.py setUpClass [ line:41 ] ==================== 准备开始执行销售方发票信息接口测试 ====================
 Wed, 01 Apr 2020 21:41:15  INFO http_request.py request [ line:38 ] 正在发送请求，请求地址：https://fsc-test.manshang.com/api/auth/login，请求参数：{'phone': '15733100728', 'code': '123456'}
 Wed, 01 Apr 2020 21:41:15  INFO http_request.py request [ line:38 ] 正在发送请求，请求地址：https://fsc-test.manshang.com/api/auth/login，请求参数：{'phone': '15733100728', 'code': '123456'}
 Wed, 01 Apr 2020 21:41:15  INFO test_sellset.py tearDownClass [ line:48 ] ==================== 销售方发票信息测试执行完毕 ====================
 Wed, 01 Apr 2020 21:41:35  INFO test_login.py setUpClass [ line:39 ] ==================== 准备开始执行登录接口测试 ====================
 Wed, 01 Apr 2020 21:41:35  INFO http_request.py request [ line:38 ] 正在发送请求，请求地址：https://fsc-test.manshang.com/api/auth/login，请求参数：{'phone': '15733100728', 'code': '123456'}
 Wed, 01 Apr 2020 21:41:35  ERROR test_login.py test_login [ line:75 ]  :: {'code': 500, 'msg': '登录失败'} != {'code': 200, 'msg': 'ok'}
Traceback (most recent call last):
  File "/Applications/software/PyCharm.app/Contents/helpers/pycharm/teamcity/diff_tools.py", line 32, in _patched_equals
    old(self, first, second, msg)
  File "/usr/local/Cellar/python/3.7.4_1/Frameworks/Python.framework/Versions/3.7/lib/python3.7/unittest/case.py", line 852, in assertEqual
    assertion_func(first, second, msg=msg)
  File "/usr/local/Cellar/python/3.7.4_1/Frameworks/Python.framework/Versions/3.7/lib/python3.7/unittest/case.py", line 1151, in assertDictEqual
    self.fail(self._formatMessage(msg, standardMsg))
  File "/usr/local/Cellar/python/3.7.4_1/Frameworks/Python.framework/Versions/3.7/lib/python3.7/unittest/case.py", line 693, in fail
    raise self.failureException(msg)
AssertionError: {'code': 500, 'msg': '登录失败'} != {'code': 200, 'msg': 'ok'}
- {'code': 500, 'msg': '登录失败'}
?          ^            ^^^^

+ {'code': 200, 'msg': 'ok'}
?          ^            ^^


During handling of the above exception, another exception occurred:

Traceback (most recent call last):
  File "/Users/yangli/PycharmProjects/api_fsctest/util/test_login.py", line 72, in test_login
    self.assertEqual(res, eval(case.expected_data))
  File "/Applications/software/PyCharm.app/Contents/helpers/pycharm/teamcity/diff_tools.py", line 38, in _patched_equals
    raise error
teamcity.diff_tools.EqualsAssertionError:  :: {'code': 500, 'msg': '登录失败'} != {'code': 200, 'msg': 'ok'}
 Wed, 01 Apr 2020 21:41:36  INFO test_login.py tearDownClass [ line:45 ] ==================== 登录接口测试执行完毕 ====================
